#VRML_SIM R2022a utf8
WorldInfo {
}
Viewpoint {
  orientation 0.3396217414551123 0.3108483450519765 -0.8877107519397546 1.7769485462426344
  position -1.498387674688551 4.003393158459323 3.5146699982210086
}
TexturedBackground {
  texture "stadium"
}
Robot {
  children [
    Receiver {
    }
    Emitter {
      channel -1
    }
  ]
  name "Referee"
  controller "referee_controller"
  supervisor TRUE
}
RobocupSoccerField {
  size "kid"
}
DEF Ball RobocupSoccerBall {
  translation 0 0 0.1
}
DEF red_0 Robot {
  translation -3.11 0 0.334
  children [
    DEF Body Transform {
      translation 0 0 0.02
      children [
        Shape {
          appearance Appearance {
            material Material {
              diffuseColor 1 0.4 0.4
            }
          }
          geometry Capsule {
            height 0.11
            radius 0.063
          }
        }
      ]
    }
    DEF GPS GPS {
    }
    DEF RECEIVER Receiver {
      channel -1
    }
    DEF EMITTER Emitter {
    }
    DEF SUPER_EMITTER Emitter {
      name "super_emitter"
      channel 2
    }
    DEF ACCELEROMETER Accelerometer {
      translation -0.008 0.00606 0.027
      rotation 1 0 0 3.14159
      lookupTable [
        -19.62 -19.62 0.01
        19.62 19.62 0.01
      ]
    }
    DEF GYRO Gyro {
      translation -0.008 0.006 0.029
      lookupTable [
        -8.726 -8.726 0.01
        8.726 8.726 0.01
      ]
      zAxis FALSE
    }
    DEF INERTIAL_UNIT InertialUnit {
      translation -0.008 0.006 0.029
      rotation 1 0 0 1.5708
      yAxis FALSE
    }
    DEF US1 Transform {
      translation 0.0537 -0.0341 0.0698
      rotation 0.07811751533110095 -0.44311208696380194 -0.8930561752684313 0.389797
      children [
        DEF SONAR_SHAPE Transform {
          rotation 0 1 0 1.5708
          children [
            Shape {
              appearance PBRAppearance {
                baseColor 0.4 0.4 0.4
                roughness 0.7
              }
              geometry Cylinder {
                height 0.01
                radius 0.005
              }
            }
          ]
        }
      ]
    }
    DEF US2 DistanceSensor {
      translation 0.0477 -0.0416 0.0509
      rotation -0.11247699708262791 0.5073889868395983 -0.8543449778404274 0.507745
      children [
        USE SONAR_SHAPE
      ]
      name "Sonar/Right"
      lookupTable [
        0.25 0.25 0
        2.55 2.55 0
      ]
      type "sonar"
      numberOfRays 6
      aperture 1.04
    }
    DEF US3 Transform {
      translation 0.0537 0.0341 0.0698
      rotation -0.07811751533110095 -0.44311208696380194 0.8930561752684313 0.389797
      children [
        USE SONAR_SHAPE
      ]
    }
    DEF US4 DistanceSensor {
      translation 0.0477 0.0416 0.0509
      rotation 0.11247699708262791 0.5073889868395983 0.8543449778404274 0.507745
      children [
        USE SONAR_SHAPE
      ]
      name "Sonar/Left"
      lookupTable [
        0.25 0.25 0
        2.55 2.55 0
      ]
      type "sonar"
      numberOfRays 6
      aperture 1.04
    }
    DEF HeadYaw Hinge2Joint {
      jointParameters HingeJointParameters {
        axis 0 0 1
        anchor 0 0 0.1265
      }
      jointParameters2 JointParameters {
        axis 0 1 0
      }
      device [
        RotationalMotor {
          name "HeadYaw"
          maxVelocity 8.26797
          minPosition -2.08567
          maxPosition 2.08567
          maxTorque 4
        }
        PositionSensor {
          name "HeadYawS"
        }
      ]
      device2 [
        RotationalMotor {
          name "HeadPitch"
          maxVelocity 7.19407
          minPosition -0.671952
          maxPosition 0.514872
          maxTorque 5
        }
        PositionSensor {
          name "HeadPitchS"
        }
      ]
      endPoint Solid {
        translation 0 0 0.1265
        rotation 0 1 0 0
        children [
          DEF HEAD_SLOT Transform {
            translation 0 0 0.05353
            rotation 1 0 0 1.5707996938995747
            children [
              Shape {
                appearance Appearance {
                  material Material {
                  }
                }
                geometry Capsule {
                  height 0.04
                  radius 0.05
                }
              }
            ]
          }
          DEF NECK Transform {
            rotation 0 0 1 -0.785395
            children [
              Shape {
                appearance DEF MAIN_SKIN_APP PBRAppearance {
                  roughness 0.8
                  metalness 0
                }
                geometry Cylinder {
                  bottom FALSE
                  height 0.01
                  radius 0.016
                  top FALSE
                  subdivision 4
                }
              }
            ]
          }
          Camera {
            translation 0.05871 0 0.06364
            rotation -0.0001899999929209804 0.9999999627420021 0.0001959999926974324 0.020946
            name "CameraTop"
            fieldOfView 1.064
            width 160
            height 120
            near 0.002
          }
          Camera {
            translation 0.05071 0 0.01774
            rotation 0 1 0 0.692901
            name "CameraBottom"
            width 160
            height 120
            near 0.002
          }
        ]
        name "head"
        contactMaterial "NAO material"
        boundingObject Transform {
          translation 0 0 0.055
          rotation 1 0 0 -1.5708
          children [
            Capsule {
              height 0.04
              radius 0.05
              subdivision 16
            }
          ]
        }
        physics Physics {
          density -1
          mass 0.68375
          centerOfMass [
            -0.000992693 0 0.0434047
          ]
          inertiaMatrix [
            0.000616403 0.00226289 0.00249657
            4.09863e-05 -3.61413e-05 8.73519e-06
          ]
        }
      }
    }
    DEF RShoulderPitch Hinge2Joint {
      jointParameters HingeJointParameters {
        axis 0 1 0
        anchor 0 -0.098 0.1
      }
      jointParameters2 JointParameters {
      }
      device [
        RotationalMotor {
          name "RShoulderPitch"
          maxVelocity 8.26797
          minPosition -2.08567
          maxPosition 2.08567
          maxTorque 4
        }
        PositionSensor {
          name "RShoulderPitchS"
        }
      ]
      device2 [
        RotationalMotor {
          name "RShoulderRoll"
          maxVelocity 7.19407
          minPosition -1.32645
          maxPosition 0.314159
          maxTorque 5
        }
        PositionSensor {
          name "RShoulderRollS"
        }
      ]
      endPoint Solid {
        translation 0 -0.098 0.1
        rotation 0 1 0 0
        children [
          Transform {
            translation 0.029 -0.005 0
            rotation 0.6236901030090795 0.5527253637243925 -0.5527253637243925 -2.03
            children [
              Shape {
                appearance Appearance {
                  material Material {
                  }
                }
                geometry Capsule {
                  height 0.1
                  radius 0.026
                }
              }
            ]
          }
          DEF RElbowYaw HingeJoint {
            jointParameters HingeJointParameters {
              anchor 0.105 -0.015 0
            }
            device [
              RotationalMotor {
                name "RElbowYaw"
                maxVelocity 8.26797
                minPosition -2.08567
                maxPosition 2.08567
                maxTorque 4
              }
              PositionSensor {
                name "RElbowYawS"
              }
            ]
            endPoint Solid {
              translation 0.105 -0.015 0
              rotation 1 0 0 0
              children [
                DEF RElbowRoll HingeJoint {
                  jointParameters HingeJointParameters {
                    axis 0 0 1
                  }
                  device [
                    RotationalMotor {
                      name "RElbowRoll"
                      maxVelocity 7.19407
                      maxPosition 1.54462
                      maxTorque 5
                    }
                    PositionSensor {
                      name "RElbowRollS"
                    }
                  ]
                  endPoint Solid {
                    children [
                      DEF RWristYaw HingeJoint {
                        jointParameters HingeJointParameters {
                          anchor 0.05595 0 0
                        }
                        device [
                          RotationalMotor {
                            name "RWristYaw"
                            maxVelocity 24.6229
                            minPosition -1.82387
                            maxPosition 1.82387
                            maxTorque 1.5
                          }
                          PositionSensor {
                            name "RWristYawS"
                          }
                        ]
                        endPoint Solid {
                          translation 0.05595 0 0
                          rotation 1 0 0 0
                          children [
                            Transform {
                              translation 0.057 0 0.014
                              rotation 0 1 0 -0.15
                              children [
                                Shape {
                                  appearance Appearance {
                                    material Material {
                                    }
                                  }
                                  geometry Cylinder {
                                    height 0.02
                                    radius 0.03
                                  }
                                }
                              ]
                            }
                            Transform {
                              translation 0.04 0 0
                              rotation 0 1 0 -0.7
                              children [
                                Shape {
                                  appearance Appearance {
                                    material Material {
                                    }
                                  }
                                  geometry Box {
                                    size 0.035 0.04 0.04
                                  }
                                }
                              ]
                            }
                          ]
                          contactMaterial "NAO material"
                          boundingObject DEF HAND_BO Group {
                            children [
                              Transform {
                                translation 0.057 0 0.014
                                rotation 0 1 0 -0.15
                                children [
                                  Cylinder {
                                    height 0.02
                                    radius 0.03
                                  }
                                ]
                              }
                              Transform {
                                translation 0.04 0 0
                                rotation 0 1 0 -0.7
                                children [
                                  Box {
                                    size 0.035 0.04 0.04
                                  }
                                ]
                              }
                            ]
                          }
                          physics Physics {
                            density -1
                            mass 0.18533
                            centerOfMass [
                              0.03434 0.00088 0.00308
                            ]
                            inertiaMatrix [
                              7.05493e-05 0.000356062 0.000351919
                              5.71599e-06 -2.24744e-05 3.17771e-06
                            ]
                          }
                        }
                      }
                      Transform {
                        translation 0.03 -0.003 0.005
                        rotation -0.5276871742310365 -0.6006439236985851 0.6006439236985851 2.17
                        children [
                          Shape {
                            appearance Appearance {
                              material Material {
                              }
                            }
                            geometry Capsule {
                              height 0.025
                              radius 0.022
                            }
                          }
                        ]
                      }
                    ]
                    name "right wrist"
                    model "Nao right wrist H25"
                    contactMaterial "NAO material"
                    boundingObject Transform {
                      translation 0.03 -0.003 0.005
                      rotation -0.5276627098855814 -0.6006556697532967 0.6006536697543964 2.170531
                      children [
                        DEF WHIRST_BO Capsule {
                          height 0.025
                          radius 0.022
                          subdivision 16
                        }
                      ]
                    }
                    physics Physics {
                      density -1
                      mass 0.07761
                      centerOfMass [
                        0.02556 -0.00281 0.00076
                      ]
                      inertiaMatrix [
                        2.53907e-05 8.92204e-05 8.72484e-05
                        2.33243e-06 -6.0117e-07 2.694e-08
                      ]
                    }
                  }
                }
                Shape {
                  appearance Appearance {
                    material Material {
                    }
                  }
                  geometry Sphere {
                    radius 0.02
                  }
                }
              ]
              contactMaterial "NAO material"
              boundingObject DEF ELBOW_BO Sphere {
                radius 0.02
              }
              physics Physics {
                density -1
                mass 0.06483
                centerOfMass [
                  -0.02744 0 -0.00014
                ]
                inertiaMatrix [
                  5.59715e-06 7.54331e-05 7.64434e-05
                  4.21e-09 4.319e-08 -1.84e-09
                ]
              }
            }
          }
        ]
        name "RShoulder"
        contactMaterial "NAO material"
        boundingObject Transform {
          translation 0.029 -0.005 0
          rotation 0.6238046756625122 0.5526617126521834 -0.5526597126532233 -2.026117
          children [
            DEF SHOULDER_BO Capsule {
              height 0.1
              radius 0.026
              subdivision 16
            }
          ]
        }
        physics Physics {
          density -1
          mass 0.25081
          centerOfMass [
            0.0148309 0.00633711 0.00212777
          ]
          inertiaMatrix [
            0.000390368 0.00015578 0.00026769
            -0.000126182 1.89718e-05 2.00601e-05
          ]
        }
      }
    }
    DEF LShoulderPitch Hinge2Joint {
      jointParameters HingeJointParameters {
        axis 0 1 0
        anchor 0 0.098 0.1
      }
      jointParameters2 JointParameters {
      }
      device [
        RotationalMotor {
          name "LShoulderPitch"
          maxVelocity 8.26797
          minPosition -2.08567
          maxPosition 2.08567
          maxTorque 4
        }
        PositionSensor {
          name "LShoulderPitchS"
        }
      ]
      device2 [
        RotationalMotor {
          name "LShoulderRoll"
          maxVelocity 7.19407
          minPosition -0.314159
          maxPosition 1.32645
          maxTorque 5
        }
        PositionSensor {
          name "LShoulderRollS"
        }
      ]
      endPoint Solid {
        translation 0 0.098 0.1
        rotation 0 1 0 0
        children [
          Transform {
            translation 0.029 0.005 0
            rotation 0.6236901030090795 -0.5527253637243925 0.5527253637243925 -2.03
            children [
              Shape {
                appearance Appearance {
                  material Material {
                  }
                }
                geometry Capsule {
                  height 0.1
                  radius 0.026
                }
              }
            ]
          }
          DEF LElbowYaw HingeJoint {
            jointParameters HingeJointParameters {
              anchor 0.105 0.015 0
            }
            device [
              RotationalMotor {
                name "LElbowYaw"
                maxVelocity 8.26797
                minPosition -2.08567
                maxPosition 2.08567
                maxTorque 4
              }
              PositionSensor {
                name "LElbowYawS"
              }
            ]
            endPoint Solid {
              translation 0.105 0.015 0
              rotation 1 0 0 0
              children [
                DEF LElbowRoll HingeJoint {
                  jointParameters HingeJointParameters {
                    axis 0 0 1
                  }
                  device [
                    RotationalMotor {
                      name "LElbowRoll"
                      maxVelocity 7.19407
                      minPosition -1.54462
                      maxTorque 5
                    }
                    PositionSensor {
                      name "LElbowRollS"
                    }
                  ]
                  endPoint Solid {
                    children [
                      DEF LWristYaw HingeJoint {
                        jointParameters HingeJointParameters {
                          anchor 0.05595 0 0
                        }
                        device [
                          RotationalMotor {
                            name "LWristYaw"
                            maxVelocity 24.6229
                            minPosition -1.82387
                            maxPosition 1.82387
                            maxTorque 1.5
                          }
                          PositionSensor {
                            name "LWristYawS"
                          }
                        ]
                        endPoint Solid {
                          translation 0.05595 0 0
                          rotation 1 0 0 0
                          children [
                            Transform {
                              translation 0.057 0 0.014
                              rotation 0 1 0 -0.15
                              children [
                                Shape {
                                  appearance Appearance {
                                    material Material {
                                    }
                                  }
                                  geometry Cylinder {
                                    height 0.02
                                    radius 0.03
                                  }
                                }
                              ]
                            }
                            Transform {
                              translation 0.04 0 0
                              rotation 0 1 0 -0.7
                              children [
                                Shape {
                                  appearance Appearance {
                                    material Material {
                                    }
                                  }
                                  geometry Box {
                                    size 0.035 0.04 0.04
                                  }
                                }
                              ]
                            }
                          ]
                          contactMaterial "NAO material"
                          boundingObject DEF HAND_BO Group {
                            children [
                              Transform {
                                translation 0.057 0 0.014
                                rotation 0 1 0 -0.15
                                children [
                                  Cylinder {
                                    height 0.02
                                    radius 0.03
                                  }
                                ]
                              }
                              Transform {
                                translation 0.04 0 0
                                rotation 0 1 0 -0.7
                                children [
                                  Box {
                                    size 0.035 0.04 0.04
                                  }
                                ]
                              }
                            ]
                          }
                          physics Physics {
                            density -1
                            mass 0.18533
                            centerOfMass [
                              0.03434 -0.00088 0.00308
                            ]
                            inertiaMatrix [
                              7.05493e-05 0.000356062 0.000351919
                              5.71599e-06 -2.24744e-05 3.17771e-06
                            ]
                          }
                        }
                      }
                      Transform {
                        translation 0.03 0.003 0.005
                        rotation -0.5276871742310365 0.6006439236985851 -0.6006439236985851 2.17
                        children [
                          Shape {
                            appearance Appearance {
                              material Material {
                              }
                            }
                            geometry Capsule {
                              height 0.025
                              radius 0.022
                            }
                          }
                        ]
                      }
                    ]
                    name "left wrist"
                    model "Nao left wrist H25"
                    contactMaterial "NAO material"
                    boundingObject Transform {
                      translation 0.03 0.003 0.005
                      rotation -0.5276627098855814 0.6006556697532967 -0.6006536697543964 2.170531
                      children [
                        DEF WHIRST_BO Capsule {
                          height 0.025
                          radius 0.022
                          subdivision 16
                        }
                      ]
                    }
                    physics Physics {
                      density -1
                      mass 0.07761
                      centerOfMass [
                        0.02556 0.00281 0.00076
                      ]
                      inertiaMatrix [
                        2.53322e-05 8.91322e-05 8.72873e-05
                        -2.34271e-06 7.459e-08 -2.655e-08
                      ]
                    }
                  }
                }
                Shape {
                  appearance Appearance {
                    material Material {
                    }
                  }
                  geometry Sphere {
                    radius 0.02
                  }
                }
              ]
              contactMaterial "NAO material"
              boundingObject USE ELBOW_BO
              physics Physics {
                density -1
                mass 0.06483
                centerOfMass [
                  -0.02744 0 -0.00014
                ]
                inertiaMatrix [
                  5.59715e-06 7.54331e-05 7.64434e-05
                  4.21e-09 4.319e-08 -1.84e-09
                ]
              }
            }
          }
        ]
        name "LShoulder"
        contactMaterial "NAO material"
        boundingObject Transform {
          translation 0.029 0.005 0
          rotation 0.6238046756625122 -0.5526617126521834 0.5526597126532233 -2.026117
          children [
            USE SHOULDER_BO
          ]
        }
        physics Physics {
          density -1
          mass 0.25081
          centerOfMass [
            0.0148309 -0.00633711 0.00212777
          ]
          inertiaMatrix [
            0.00039431 0.00013956 0.000254973
            9.6588e-05 3.57699e-07 3.29807e-05
          ]
        }
      }
    }
    DEF RHipYawPitch HingeJoint {
      jointParameters HingeJointParameters {
        axis 0 0.707107 0.707107
        anchor 0 -0.05 -0.085
      }
      device [
        RotationalMotor {
          name "RHipYawPitch"
          maxVelocity 4.16174
          minPosition -1.14529
          maxPosition 0.740718
          maxTorque 14.8
        }
        PositionSensor {
          name "RHipYawPitchS"
        }
      ]
      endPoint Solid {
        translation 0 -0.05 -0.085
        rotation 0 0.7071067811865476 0.7071067811865476 0
        children [
          DEF RHipRoll HingeJoint {
            jointParameters HingeJointParameters {
            }
            device [
              RotationalMotor {
                name "RHipRoll"
                maxVelocity 4.16174
                minPosition -0.738274
                maxPosition 0.449597
                maxTorque 14.8
              }
              PositionSensor {
                name "RHipRollS"
              }
            ]
            endPoint Solid {
              rotation 1 0 0 0
              children [
                DEF HIP_ROLL_CYL_TRANS Transform {
                  translation -0.019 0 0
                  rotation 0 0 1 1.5708
                  children [
                    Shape {
                      appearance PBRAppearance {
                        baseColor 0.8 0.8 0.8
                        roughness 1
                        metalness 0
                      }
                      geometry Cylinder {
                        height 0.066
                        radius 0.014
                        top FALSE
                      }
                    }
                  ]
                }
                Transform {
                  translation -0.022 0 0
                  children [
                    Shape {
                      appearance Appearance {
                        material Material {
                        }
                      }
                      geometry Box {
                        size 0.08 0.05 0.05
                      }
                    }
                  ]
                }
                DEF RHipPitch HingeJoint {
                  jointParameters HingeJointParameters {
                    axis 0 1 0
                  }
                  device [
                    RotationalMotor {
                      name "RHipPitch"
                      maxVelocity 6.40239
                      minPosition -1.77378
                      maxPosition 0.48398
                      maxTorque 9.8
                    }
                    PositionSensor {
                      name "RHipPitchS"
                    }
                  ]
                  endPoint Solid {
                    rotation 0 1 0 0
                    children [
                      DEF RKneePitch HingeJoint {
                        jointParameters HingeJointParameters {
                          axis 0 1 0
                          anchor 0 0 -0.1
                        }
                        device [
                          RotationalMotor {
                            name "RKneePitch"
                            maxVelocity 6.40239
                            minPosition -0.0923279
                            maxPosition 2.11255
                            maxTorque 9.8
                          }
                          PositionSensor {
                            name "RKneePitchS"
                          }
                        ]
                        endPoint Solid {
                          translation 0 0 -0.1
                          rotation 0 1 0 0
                          children [
                            DEF RAnklePitch HingeJoint {
                              jointParameters HingeJointParameters {
                                axis 0 1 0
                                anchor 0 0 -0.1029
                              }
                              device [
                                RotationalMotor {
                                  name "RAnklePitch"
                                  maxVelocity 6.40239
                                  minPosition -1.1863
                                  maxPosition 0.932006
                                  maxTorque 9.8
                                }
                                PositionSensor {
                                  name "RAnklePitchS"
                                }
                              ]
                              endPoint Solid {
                                translation 0 0 -0.1029
                                rotation 0 1 0 0
                                children [
                                  DEF RAnkleRoll HingeJoint {
                                    jointParameters HingeJointParameters {
                                    }
                                    device [
                                      RotationalMotor {
                                        name "RAnkleRoll"
                                        maxVelocity 4.16174
                                        minPosition -0.768992
                                        maxPosition 0.397935
                                        maxTorque 14.8
                                      }
                                      PositionSensor {
                                        name "RAnkleRollS"
                                      }
                                    ]
                                    endPoint Solid {
                                      rotation 1 0 0 0
                                      children [
                                        DEF RFsr TouchSensor {
                                          translation 0.02 -0.007 -0.041
                                          rotation 0 0 1 3.1416
                                          name "RFsr"
                                          contactMaterial "NAO foot material"
                                          boundingObject DEF FOOT_Box Box {
                                            size 0.147 0.089 0.01
                                          }
                                          physics DEF FSR_Physics Physics {
                                            density -1
                                            mass 0.08057
                                          }
                                          type "force-3d"
                                          lookupTable []
                                        }
                                        DEF RFOOT_RBUMPER TouchSensor {
                                          translation 0.09 -0.022 -0.023
                                          children [
                                            Transform {
                                              translation -0.09 0.022 0.023
                                            }
                                          ]
                                          name "RFoot/Bumper/Right"
                                          boundingObject DEF BUMPER_BO Transform {
                                            translation 0.0075 0 0
                                            children [
                                              Box {
                                                size 0.005 0.025 0.01
                                              }
                                            ]
                                          }
                                          lookupTable []
                                        }
                                        DEF RFOOT_LBUMPER TouchSensor {
                                          translation 0.09 0.012 -0.023
                                          name "RFoot/Bumper/Left"
                                          boundingObject USE BUMPER_BO
                                          lookupTable []
                                        }
                                        Transform {
                                          translation 0.02 -0.007 -0.025
                                          children [
                                            Shape {
                                              appearance Appearance {
                                                material Material {
                                                }
                                              }
                                              geometry Box {
                                                size 0.148 0.09 0.02
                                              }
                                            }
                                          ]
                                        }
                                      ]
                                      contactMaterial "NAO foot material"
                                      boundingObject Transform {
                                        translation 0.02 -0.007 -0.025
                                        children [
                                          DEF FOOT_BO Box {
                                            size 0.148 0.09 0.02
                                          }
                                        ]
                                      }
                                      physics Physics {
                                        density -1
                                        mass 0.09127
                                        centerOfMass [
                                          0.02542 -0.0033 -0.03239
                                        ]
                                        inertiaMatrix [
                                          0.000269302 0.000643474 0.000525035
                                          5.87505e-06 0.000139133 -1.88492e-05
                                        ]
                                      }
                                    }
                                  }
                                  Shape {
                                    appearance Appearance {
                                      material Material {
                                      }
                                    }
                                    geometry Box {
                                      size 0.078 0.027 0.05
                                    }
                                  }
                                ]
                                contactMaterial "NAO material"
                                boundingObject DEF ANKLE_PITCH_BO Box {
                                  size 0.078 0.027 0.05
                                }
                                physics Physics {
                                  density -1
                                  mass 0.13416
                                  centerOfMass [
                                    0.00045 -0.00029 0.00685
                                  ]
                                  inertiaMatrix [
                                    3.85081e-05 7.43108e-05 5.49131e-05
                                    6.434e-08 3.87466e-06 -4.58e-09
                                  ]
                                }
                              }
                            }
                            Transform {
                              translation 0.01 0 -0.055
                              rotation 0 1 0 0.2
                              children [
                                Shape {
                                  appearance Appearance {
                                    material Material {
                                    }
                                  }
                                  geometry Box {
                                    size 0.06 0.08 0.11
                                  }
                                }
                              ]
                            }
                          ]
                          contactMaterial "NAO material"
                          boundingObject DEF TIBIA_BO Transform {
                            translation 0.01 0 -0.055
                            rotation 0 1 0 0.2
                            children [
                              Box {
                                size 0.06 0.08 0.11
                              }
                            ]
                          }
                          physics Physics {
                            density -1
                            mass 0.30142
                            centerOfMass [
                              0.00453 -0.00225 -0.04936
                            ]
                            inertiaMatrix [
                              0.00118283 0.00112828 0.000191453
                              -8.965e-07 2.79969e-05 -3.8476e-05
                            ]
                          }
                        }
                      }
                      Transform {
                        translation 0 0 -0.055
                        rotation 0 1 0 -0.3831853071795859
                        children [
                          Shape {
                            appearance Appearance {
                              material Material {
                              }
                            }
                            geometry Box {
                              size 0.06 0.08 0.13
                            }
                          }
                        ]
                      }
                    ]
                    contactMaterial "NAO material"
                    boundingObject DEF FEMUR_BO Transform {
                      translation 0 0 -0.055
                      rotation 0 1 0 5.9
                      children [
                        Box {
                          size 0.06 0.08 0.13
                        }
                      ]
                    }
                    physics Physics {
                      density -1
                      mass 0.38968
                      centerOfMass [
                        0.00138 -0.00221 -0.05373
                      ]
                      inertiaMatrix [
                        0.00163748 0.00159221 0.000303978
                        -8.3954e-07 8.5883e-05 -3.91763e-05
                      ]
                    }
                  }
                }
              ]
              contactMaterial "NAO material"
              boundingObject DEF HIP_ROLL_BO Transform {
                translation -0.022 0 0
                children [
                  Box {
                    size 0.08 0.05 0.05
                  }
                ]
              }
              physics Physics {
                density -1
                mass 0.14053
                centerOfMass [
                  -0.01549 -0.00029 -0.00515
                ]
                inertiaMatrix [
                  2.75865e-05 9.827e-05 8.81033e-05
                  -1.919e-08 -4.10822e-06 2.51e-09
                ]
              }
            }
          }
          Shape {
            appearance Appearance {
              material Material {
              }
            }
            geometry Sphere {
              radius 0.01
            }
          }
        ]
        name "RHip"
        contactMaterial "NAO material"
        boundingObject Sphere {
          radius 0.01
        }
        physics Physics {
          density -1
          mass 0.06981
          centerOfMass [
            -0.00781 0.01114 0.02661
          ]
          inertiaMatrix [
            8.9972e-05 0.000105526 6.68872e-05
            5.00219e-06 1.27352e-05 -2.77008e-05
          ]
        }
      }
    }
    DEF LHipYawPitch HingeJoint {
      jointParameters HingeJointParameters {
        axis 0 0.707107 -0.707107
        anchor 0 0.05 -0.085
      }
      device [
        RotationalMotor {
          name "LHipYawPitch"
          maxVelocity 4.16174
          minPosition -1.14529
          maxPosition 0.740718
          maxTorque 14.8
        }
        PositionSensor {
          name "LHipYawPitchS"
        }
      ]
      endPoint Solid {
        translation 0 0.05 -0.085
        rotation 0 0.7071067811865476 -0.7071067811865476 0
        children [
          DEF LHipRoll HingeJoint {
            jointParameters HingeJointParameters {
            }
            device [
              RotationalMotor {
                name "LHipRoll"
                maxVelocity 4.16174
                minPosition -0.379435
                maxPosition 0.79046
                maxTorque 14.8
              }
              PositionSensor {
                name "LHipRollS"
              }
            ]
            endPoint Solid {
              rotation 1 0 0 0
              children [
                USE HIP_ROLL_CYL_TRANS
                Transform {
                  translation -0.022 0 0
                  children [
                    Shape {
                      appearance Appearance {
                        material Material {
                        }
                      }
                      geometry Box {
                        size 0.08 0.05 0.05
                      }
                    }
                  ]
                }
                DEF LHipPitch HingeJoint {
                  jointParameters HingeJointParameters {
                    axis 0 1 0
                  }
                  device [
                    RotationalMotor {
                      name "LHipPitch"
                      maxVelocity 6.40239
                      minPosition -1.77378
                      maxPosition 0.48398
                      maxTorque 9.8
                    }
                    PositionSensor {
                      name "LHipPitchS"
                    }
                  ]
                  endPoint Solid {
                    rotation 0 1 0 0
                    children [
                      DEF LKneePitch HingeJoint {
                        jointParameters HingeJointParameters {
                          axis 0 1 0
                          anchor 0 0 -0.1
                        }
                        device [
                          RotationalMotor {
                            name "LKneePitch"
                            maxVelocity 6.40239
                            minPosition -0.0923279
                            maxPosition 2.11255
                            maxTorque 9.8
                          }
                          PositionSensor {
                            name "LKneePitchS"
                          }
                        ]
                        endPoint Solid {
                          translation 0 0 -0.1
                          rotation 0 1 0 0
                          children [
                            DEF LAnklePitch HingeJoint {
                              jointParameters HingeJointParameters {
                                axis 0 1 0
                                anchor 0 0 -0.1029
                              }
                              device [
                                RotationalMotor {
                                  name "LAnklePitch"
                                  maxVelocity 6.40239
                                  minPosition -1.18944
                                  maxPosition 0.922581
                                  maxTorque 9.8
                                }
                                PositionSensor {
                                  name "LAnklePitchS"
                                }
                              ]
                              endPoint Solid {
                                translation 0 0 -0.1029
                                rotation 0 1 0 0
                                children [
                                  DEF LAnkleRoll HingeJoint {
                                    jointParameters HingeJointParameters {
                                    }
                                    device [
                                      RotationalMotor {
                                        name "LAnkleRoll"
                                        maxVelocity 4.16174
                                        minPosition -0.39788
                                        maxPosition 0.769001
                                        maxTorque 14.8
                                      }
                                      PositionSensor {
                                        name "LAnkleRollS"
                                      }
                                    ]
                                    endPoint Solid {
                                      rotation 1 0 0 0
                                      children [
                                        DEF LEFT_FOOT_SLOT Transform {
                                          translation 0.0254 0.00332 -0.03241
                                        }
                                        DEF LFsr TouchSensor {
                                          translation 0.02 0.007 -0.041
                                          rotation 0 0 1 3.1416
                                          name "LFsr"
                                          contactMaterial "NAO foot material"
                                          boundingObject USE FOOT_Box
                                          physics USE FSR_Physics
                                          type "force-3d"
                                          lookupTable []
                                        }
                                        DEF LFOOT_LBUMPER TouchSensor {
                                          translation 0.09 0.022 -0.023
                                          name "LFoot/Bumper/Left"
                                          boundingObject USE BUMPER_BO
                                          lookupTable []
                                        }
                                        DEF LFOOT_RBUMPER TouchSensor {
                                          translation 0.09 -0.012 -0.023
                                          name "LFoot/Bumper/Right"
                                          boundingObject USE BUMPER_BO
                                          lookupTable []
                                        }
                                        Transform {
                                          translation 0.02 0.007 -0.025
                                          children [
                                            Shape {
                                              appearance Appearance {
                                                material Material {
                                                }
                                              }
                                              geometry Box {
                                                size 0.148 0.09 0.02
                                              }
                                            }
                                          ]
                                        }
                                      ]
                                      contactMaterial "NAO foot material"
                                      boundingObject Transform {
                                        translation 0.02 0.007 -0.025
                                        children [
                                          USE FOOT_BO
                                        ]
                                      }
                                      physics Physics {
                                        density -1
                                        mass 0.09127
                                        centerOfMass [
                                          0.02542 0.0033 -0.03239
                                        ]
                                        inertiaMatrix [
                                          0.000269442 0.000644343 0.000525757
                                          -5.69572e-06 0.000139379 1.87409e-05
                                        ]
                                      }
                                    }
                                  }
                                ]
                                contactMaterial "NAO material"
                                boundingObject USE ANKLE_PITCH_BO
                                physics Physics {
                                  density -1
                                  mass 0.13416
                                  centerOfMass [
                                    0.00045 0.00029 0.00685
                                  ]
                                  inertiaMatrix [
                                    3.85098e-05 7.42653e-05 5.48654e-05
                                    -2.634e-08 3.86194e-06 1.834e-08
                                  ]
                                }
                              }
                            }
                            Transform {
                              translation 0.01 0 -0.055
                              rotation 0 1 0 0.2
                              children [
                                Shape {
                                  appearance Appearance {
                                    material Material {
                                    }
                                  }
                                  geometry Box {
                                    size 0.06 0.08 0.11
                                  }
                                }
                              ]
                            }
                          ]
                          contactMaterial "NAO material"
                          boundingObject USE TIBIA_BO
                          physics Physics {
                            density -1
                            mass 0.30142
                            centerOfMass [
                              0.00453 0.00225 -0.04936
                            ]
                            inertiaMatrix [
                              0.00118208 0.00112865 0.000193227
                              6.3362e-07 3.6497e-05 3.94952e-05
                            ]
                          }
                        }
                      }
                      Transform {
                        translation 0 0 -0.055
                        rotation 0 1 0 -0.3831853071795859
                        children [
                          Shape {
                            appearance Appearance {
                              material Material {
                              }
                            }
                            geometry Box {
                              size 0.06 0.08 0.13
                            }
                          }
                        ]
                      }
                    ]
                    contactMaterial "NAO material"
                    boundingObject USE FEMUR_BO
                    physics Physics {
                      density -1
                      mass 0.38968
                      centerOfMass [
                        0.00138 0.00221 -0.05373
                      ]
                      inertiaMatrix [
                        0.00163672 0.00159107 0.000303743
                        9.2451e-07 8.53067e-05 3.83616e-05
                      ]
                    }
                  }
                }
              ]
              contactMaterial "NAO material"
              boundingObject USE HIP_ROLL_BO
              physics Physics {
                density -1
                mass 0.14053
                centerOfMass [
                  -0.01549 0.00029 -0.00515
                ]
                inertiaMatrix [
                  2.75835e-05 9.82706e-05 8.80997e-05
                  -2.233e-08 -4.08164e-06 -4.19e-09
                ]
              }
            }
          }
          Shape {
            appearance Appearance {
              material Material {
              }
            }
            geometry Sphere {
              radius 0.01
            }
          }
        ]
        name "LHip"
        contactMaterial "NAO material"
        boundingObject Sphere {
          radius 0.01
        }
        physics Physics {
          density -1
          mass 0.06981
          centerOfMass [
            -0.00781 -0.01114 0.02661
          ]
          inertiaMatrix [
            8.15023e-05 0.000101326 6.26236e-05
            -4.99449e-06 1.27482e-05 2.34547e-05
          ]
        }
      }
    }
    DEF ARMS_AXIS Transform {
      translation 0 0 0.1
      rotation 1 0 0 1.5708
      children [
        Shape {
          appearance DEF STRUCTURE_APP PBRAppearance {
            baseColor 0.419608 0.419608 0.419608
            roughness 0.6
            metalness 0
          }
          geometry Cylinder {
            bottom FALSE
            height 0.2
            radius 0.017
            top FALSE
            subdivision 6
          }
        }
      ]
    }
  ]
  name "0"
  model "NAO_H25_V50"
  contactMaterial "NAO material"
  boundingObject Transform {
    translation 0 0 0.02
    children [
      Capsule {
        height 0.11
        radius 0.063
        subdivision 16
      }
    ]
  }
  physics Physics {
    density -1
    mass 1.04956
    centerOfMass [
      -0.00413 0 0.04342
    ]
    inertiaMatrix [
      0.00506234 0.00488014 0.0016103
      1.43116e-05 0.000155191 -2.70793e-05
    ]
  }
  controller "player_controller"
}
DEF red_1 Nao {
  translation -2.35 0 0.334
  name "1"
  controller "void"
  channel -1
}
DEF red_2 Nao {
  translation -0.86 0 0.334
  name "2"
  controller "void"
  channel -1
}
DEF red_3 Nao {
  translation -1.69 0 0.334
  name "3"
  controller "player_controller"
  channel -1
}
DEF blue_0 Nao {
  translation 2.1 0 0.334
  name "4"
  color 0 0 1
  controller "void"
  channel -1
}
DEF blue_1 Nao {
  translation -0.44 0 0.334
  name "5"
  color 0 0 1
  controller "void"
  channel -1
}
DEF blue_2 Nao {
  translation 0.48 0 0.334
  name "6"
  color 0 0 1
  controller "void"
  channel -1
}
DEF blue_3 Nao {
  translation 1.57 0 0.334
  name "7"
  color 0 0 1
  controller "void"
  channel -1
}
TexturedBackgroundLight {
  texture "stadium"
}
